[2024-08-05T19:15:07.875+0000] {local_task_job_runner.py:120} INFO - ::group::Pre task execution logs
[2024-08-05T19:15:07.917+0000] {taskinstance.py:2076} INFO - Dependencies all met for dep_context=non-requeueable deps ti=<TaskInstance: reddit_data_pipeline.s3_upload manual__2024-08-05T19:14:56.683960+00:00 [queued]>
[2024-08-05T19:15:07.935+0000] {taskinstance.py:2076} INFO - Dependencies all met for dep_context=requeueable deps ti=<TaskInstance: reddit_data_pipeline.s3_upload manual__2024-08-05T19:14:56.683960+00:00 [queued]>
[2024-08-05T19:15:07.936+0000] {taskinstance.py:2306} INFO - Starting attempt 1 of 1
[2024-08-05T19:15:07.960+0000] {taskinstance.py:2330} INFO - Executing <Task(PythonOperator): s3_upload> on 2024-08-05 19:14:56.683960+00:00
[2024-08-05T19:15:07.983+0000] {standard_task_runner.py:64} INFO - Started process 117 to run task
[2024-08-05T19:15:07.990+0000] {standard_task_runner.py:90} INFO - Running: ['airflow', 'tasks', 'run', 'reddit_data_pipeline', 's3_upload', 'manual__2024-08-05T19:14:56.683960+00:00', '--job-id', '21', '--raw', '--subdir', 'DAGS_FOLDER/reddit_dag.py', '--cfg-path', '/tmp/tmp4exxepfn']
[2024-08-05T19:15:07.994+0000] {standard_task_runner.py:91} INFO - Job 21: Subtask s3_upload
[2024-08-05T19:15:08.078+0000] {task_command.py:426} INFO - Running <TaskInstance: reddit_data_pipeline.s3_upload manual__2024-08-05T19:14:56.683960+00:00 [running]> on host 6af9bcc3df88
[2024-08-05T19:15:08.254+0000] {taskinstance.py:2648} INFO - Exporting env vars: AIRFLOW_CTX_DAG_OWNER='Piyush Agarwal' AIRFLOW_CTX_DAG_ID='reddit_data_pipeline' AIRFLOW_CTX_TASK_ID='s3_upload' AIRFLOW_CTX_EXECUTION_DATE='2024-08-05T19:14:56.683960+00:00' AIRFLOW_CTX_TRY_NUMBER='1' AIRFLOW_CTX_DAG_RUN_ID='manual__2024-08-05T19:14:56.683960+00:00'
[2024-08-05T19:15:08.257+0000] {taskinstance.py:430} INFO - ::endgroup::
[2024-08-05T19:15:09.201+0000] {logging_mixin.py:188} INFO - Bucket already exists
[2024-08-05T19:15:09.807+0000] {taskinstance.py:441} INFO - ::group::Post task execution logs
[2024-08-05T19:15:09.816+0000] {taskinstance.py:2905} ERROR - Task failed with exception
Traceback (most recent call last):
  File "/home/airflow/.local/lib/python3.9/site-packages/s3fs/core.py", line 113, in _error_wrapper
    return await func(*args, **kwargs)
  File "/home/airflow/.local/lib/python3.9/site-packages/aiobotocore/client.py", line 411, in _make_api_call
    raise error_class(parsed_response, operation_name)
botocore.exceptions.ClientError: An error occurred (AccessDenied) when calling the PutObject operation: Access Denied

The above exception was the direct cause of the following exception:

Traceback (most recent call last):
  File "/home/airflow/.local/lib/python3.9/site-packages/airflow/models/taskinstance.py", line 465, in _execute_task
    result = _execute_callable(context=context, **execute_callable_kwargs)
  File "/home/airflow/.local/lib/python3.9/site-packages/airflow/models/taskinstance.py", line 432, in _execute_callable
    return execute_callable(context=context, **execute_callable_kwargs)
  File "/home/airflow/.local/lib/python3.9/site-packages/airflow/models/baseoperator.py", line 401, in wrapper
    return func(self, *args, **kwargs)
  File "/home/airflow/.local/lib/python3.9/site-packages/airflow/operators/python.py", line 235, in execute
    return_value = self.execute_callable()
  File "/home/airflow/.local/lib/python3.9/site-packages/airflow/operators/python.py", line 252, in execute_callable
    return self.python_callable(*self.op_args, **self.op_kwargs)
  File "/opt/airflow/pipelines/aws_s3_pipeline.py", line 11, in upload_s3_pipeline
    upload_to_s3(s3, file_path, AWS_BUCKET_NAME, file_path.split('/')[-1])
  File "/opt/airflow/etls/aws_etl.py", line 27, in upload_to_s3
    s3.put(file_path, bucket+'/raw/'+ s3_file_name)
  File "/home/airflow/.local/lib/python3.9/site-packages/fsspec/asyn.py", line 118, in wrapper
    return sync(self.loop, func, *args, **kwargs)
  File "/home/airflow/.local/lib/python3.9/site-packages/fsspec/asyn.py", line 103, in sync
    raise return_result
  File "/home/airflow/.local/lib/python3.9/site-packages/fsspec/asyn.py", line 56, in _runner
    result[0] = await coro
  File "/home/airflow/.local/lib/python3.9/site-packages/fsspec/asyn.py", line 589, in _put
    return await _run_coros_in_chunks(
  File "/home/airflow/.local/lib/python3.9/site-packages/fsspec/asyn.py", line 268, in _run_coros_in_chunks
    result, k = await done.pop()
  File "/home/airflow/.local/lib/python3.9/site-packages/fsspec/asyn.py", line 245, in _run_coro
    return await asyncio.wait_for(coro, timeout=timeout), i
  File "/usr/local/lib/python3.9/asyncio/tasks.py", line 442, in wait_for
    return await fut
  File "/home/airflow/.local/lib/python3.9/site-packages/fsspec/callbacks.py", line 81, in func
    return await fn(path1, path2, callback=child, **kwargs)
  File "/home/airflow/.local/lib/python3.9/site-packages/s3fs/core.py", line 1196, in _put_file
    await self._call_s3(
  File "/home/airflow/.local/lib/python3.9/site-packages/s3fs/core.py", line 365, in _call_s3
    return await _error_wrapper(
  File "/home/airflow/.local/lib/python3.9/site-packages/s3fs/core.py", line 145, in _error_wrapper
    raise err
PermissionError: Access Denied
[2024-08-05T19:15:10.113+0000] {taskinstance.py:1206} INFO - Marking task as FAILED. dag_id=reddit_data_pipeline, task_id=s3_upload, run_id=manual__2024-08-05T19:14:56.683960+00:00, execution_date=20240805T191456, start_date=20240805T191507, end_date=20240805T191510
[2024-08-05T19:15:10.153+0000] {standard_task_runner.py:110} ERROR - Failed to execute job 21 for task s3_upload (Access Denied; 117)
[2024-08-05T19:15:10.230+0000] {local_task_job_runner.py:243} INFO - Task exited with return code 1
[2024-08-05T19:15:10.260+0000] {taskinstance.py:3503} INFO - 0 downstream tasks scheduled from follow-on schedule check
[2024-08-05T19:15:10.266+0000] {local_task_job_runner.py:222} INFO - ::endgroup::
